Workbook

Sheet Inicio
A1: Master Data del circuito TO-BE — descarga, transporte y almacenamiento de fertilizantes
A2: Versión 3.1 · 15/09/2026 · Actualizado con la revisión grupal del FD (workflow de recepción, transporte y depósito por buque · camión · ferrocarril). Base: v3.0 del 09/09/2026 sobre el "Modelo de sistema basado en Master Data y Operativos" (30 maestros M-01..M-30). El Excel v2.2 (MD-00..MD-37) queda como referencia secundaria: ver hoja 0-Cruce.
A4: 1. Qué es este archivo y cómo leerlo en 5 minutos
A5: Qué es un "maestro" (M) | B5: Una lista de referencia que el sistema usa todo el tiempo y cambia poco: clientes, productos, buques, plantas, balanzas. El modelo define 30 maestros numerados M-01 a M-30 en 9 dominios (2.1 Organización y contabilidad … 2.9 Parámetros generales). M-10a es el detalle físico de M-10 Depósitos (celdas · boxes · tanques).
A6: Qué es un "Operativo" | B6: El concepto central del modelo: TODO servicio (descarga, carga, transporte, almacenaje y sus combinaciones, despacho, movimiento, alquiler de maquinaria, flete, trasbordo, recepción por camión) origina un Operativo que consume la master data, se planifica progresivamente, se ejecuta, se mide, se concilia, se costea y se factura. No es un maestro: es la transacción que los usa a todos.
A7: Qué es un "atributo" | B7: Cada campo de un maestro. La hoja 2 tiene uno por fila con tipo, obligatoriedad, valores admitidos y regla. Criterio del modelo: la master data se construye con información PROPIA del objeto; lo que depende de la ocasión (la agencia de un arribo, la ocupación de una celda) vive en el LineUp / Operativo y se marca como "contextual" o "calculado".
A8: Regla general del modelo | B8: Master Data → Contrato / LineUp / Solicitud → Operativo → Planificación → Validaciones → Ejecución → Medición → Conciliación → Costeo → Facturación → KPIs.
A9: Por dónde empezar | B9: Hoja 1 (columna "Descripción") para entender cada maestro → hoja 2 filtrada por el maestro que te toca → hoja 7 para ver cómo se comporta (validaciones, alertas, ABM) → hoja 5 para saber cuándo se carga.
A10: Qué hacer en la sesión | B10: Leer las filas de tu área, marcar en la columna amarilla "Revisión en sesión" (Validado · Con cambios · Eliminar) y anotar en "Comentarios del equipo". Los atributos marcados ★ los propone el simulador y NO están en el documento del modelo: hay que validarlos o eliminarlos.
A12: 2. Leyenda de colores y símbolos
A13: Verde | B13: Maestro o atributo NUEVO respecto del Excel v2.2 (ej. M-05 Áreas; propiedad en M-11 Transporte).
A14: Ámbar | B14: Maestro que FUSIONA dos o más maestros del Excel v2.2 (ej. M-06 Clientes / Proveedores = MD-04 + MD-05 + MD-21).
A15: Violeta ★ | B15: Atributo propuesto por el simulador (no está en el documento del modelo): a validar en sesión.
A16: Amarillo | B16: Celdas para que el EQUIPO complete: estado de revisión (lista desplegable) y comentarios.
A17: "Ref. M-nn" | B17: El campo no se escribe: se elige de otro maestro (CV-6 Referencia, no texto).
A18: "Contextual" / "Calculado" | B18: Atributo que NO se carga en el ABM: contextual = depende de la ocasión y vive en el LineUp / Operativo / Contrato; calculado = lo deriva el sistema de las transacciones (ocupación, horómetro, homologado).
A19: "Alta provisoria (72 h)" | B19: Registro que se carga con datos incompletos para no frenar la operación y que tiene 72 horas para regularizarse (se usa desde la bandeja de solicitudes de cada sector).
A21: 3. Índice de hojas
A22: 1-Fichas de entidades | B22: Una fila por maestro (35 filas: M-01..M-34 + M-10a): descripción, dominio, nivel de carga, clave natural, dependencias, existe hoy, fuente de carga, administra (con los tramos de administración compartida en 17 · 31 · 32), autoriza, equivalente en el Excel v2.2 y transacciones que lo consumen. Nuevos en v3.1: M-31 Cupos de ingreso (faltaba en v3.0), M-32 Arribos ferroviarios, M-33 Régimen de turnos, M-34 Métodos seguros.
A23: 2-Atributos | B23: Los campos de cada maestro según el modelo (374 atributos): tipo de dato, obligatorio, valores admitidos, parámetro, regla, origen (Modelo / ★ Simulador / Revisión 15/09/2026), carácter (propio / contextual / calculado) y equivalente en v2.2. Nuevos en v3.1: atributo metodo_seguro (Ref. M-34) en los maestros de recursos y operación, composicion_roles en M-13, habilitada_fiscal y su vencimiento en M-26, tramo de portería en M-31, y los atributos completos de M-31, M-32, M-33 y M-34.
A24: 3-Auditoría y ciclo de vida | B24: Los 7 campos comunes a todos los maestros y los 6 estados por los que pasa cualquier alta (heredado del v2.2).
A25: 4-Convenciones | B25: Las 8 reglas de juego que valen para todo el modelo (heredado del v2.2).
A26: 5-Orden de carga | B26: En qué orden se construyen y cargan los maestros (niveles 0 a 3) según las dependencias del modelo.
A27: 6-Definiciones previas | B27: Las 10 decisiones del negocio que habilitan la carga, remapeadas a los maestros del modelo, más las decisiones abiertas y las que el propio modelo ya tomó.
A28: 7-Reglas por maestro | B28: Cómo se comporta cada maestro: validaciones, automatizaciones, alertas y pasos del ABM (heredado del v2.2 con códigos y atributos remapeados; M-17 LineUp completo).
A29: 8-Mapeo de fuentes | B29: Para la carga inicial: de qué planilla o sistema sale cada campo y cómo se transforma (remapeado a M-nn y a los nuevos nombres de atributo).
A30: 9-Tablero | B30: Avance automático: atributos y reglas por maestro y cuántos quedaron validados. No se edita.
A31: 0-Cruce v2.2 → Modelo | B31: Qué maestro del Excel v2.2 alimenta a cada maestro del modelo, qué se fusionó y qué dejó de ser maestro (modalidades, organismos, documentos exigidos, planes de mantenimiento).
A32: TX y EV | B32: Catálogo de transacciones TX-01..TX-42 y eventos EV-01..EV-17 del circuito, con los maestros del modelo que consume cada transacción.
A34: 4. Cómo modificar el archivo sin romperlo
A35: Cambiar un atributo | B35: Editá la fila en la hoja 2 (tipo, obligatorio, valores, regla) y marcá "Con cambios" en la columna amarilla.
A36: Agregar un atributo | B36: Insertá una fila dentro del bloque de su maestro en la hoja 2 y copiá el código M-nn y el nombre del maestro. El tablero lo cuenta solo.
A37: Agregar un maestro nuevo | B37: Hoja 1: nueva fila con el próximo código (M-35). Después sus atributos en la hoja 2, su nivel en la hoja 5 y sus reglas en la hoja 7.
A38: Qué NO hacer | B38: No borrar filas (marcá "Eliminar" en la columna amarilla), no renombrar hojas (el tablero las referencia), no cambiar los códigos M-nn.
A40: 5. Números y versiones
A41: Totales v3.1 | B41: 35 maestros (33 del modelo + M-10a detalle + M-31 Cupos) · 10 dominios · 374 atributos (35 propuestos ★ por el simulador · 53 incorporados en la revisión del 15/09/2026 · 15 de M-31 que faltaban) + 7 de auditoría comunes · 4 niveles de carga · 52 transacciones · 21 eventos de negocio (+ 23 eventos de trazabilidad del bus).
A42: v3.1 — 15/09/2026 | B42: Revisión grupal del FD (sesión 15/09/2026), workflow de recepción, transporte y depósito. Cambios: (1) la mercadería arriba por buque (LineUp), camión (cupos) o ferrocarril: nuevo M-32 Arribos ferroviarios; (2) LineUp, cupos y arribos se administran en forma centralizada por tramos (un sector carga, otro completa): M-17 Comercial → Planificación · M-31 Comercial → Tráfico · M-32 Comercial → Logística; (3) Comercial declara el estado aduanero de la mercadería (nacionalizada / no nacionalizada): filtro fiscal en depósitos y balanzas (M-26.habilitada_fiscal); (4) Planificación centralizada por recurso: manos (M-13 categoría × cantidad, composicion_roles), dotación propia (M-05 puesto × cantidad), choferes (M-27 cantidad); (5) turnos de 6 h parametrizados: nuevo M-33 Régimen de turnos (M-19 lo referencia); la cantidad de turnos define la duración del operativo; (6) planificado vs. realizado: TX-44 · EV-PLANREAL; (7) atributo "Método seguro": nuevo M-34 Métodos seguros (tipo de MS, documento, vencimiento, acción al vencer) referenciado desde M-05 · M-07 · M-10 · M-10a · M-11 · M-12 · M-13 · M-14 · M-25 · M-26 · M-30. Hojas actualizadas: 1, 2, 5, 6 (definiciones Nº 13–18 y decisiones D-15–D-18), 7, 8, 9, 0-Cruce, TX y EV.
A43: v3.0 — 09/09/2026 | B43: Reestructuración completa sobre el documento "Modelo de sistema basado en Master Data y Operativos" (Cristian D'Annunzio, 09/09/2026), tomado como modelo válido. Fusiones: Clientes + Proveedores + Transportistas (M-06); Productos + Familias (M-07); Plan de cuentas + Objeto operativo (M-03); Unidades de transporte con propiedad propia/tercero (M-11); Maquinaria con plan de mantenimiento como atributo (M-12); Servicios + Modalidades → Tipos de servicio como registros (M-14). Dejan de ser maestros: MD-12 Modalidad, MD-28 Plan de mantenimiento, MD-36 Organismo externo y MD-37 Documento exigido (pasan a reglas del circuito).
A44: v2.2 — 07/09/2026 | B44: Archivo anterior: 38 maestros MD-00..MD-37, 373 atributos. Se conserva como referencia secundaria.

Sheet 1-Fichas de entidades
A1: Código | B1: Maestro | C1: Descripción | D1: Dominio | E1: Nivel | F1: Clave natural | G1: Depende de | H1: Existe hoy | I1: Fuente de carga inicial | J1: Administra | K1: Autoriza | L1: Equivalente v2.2 | M1: Transacciones que lo consumen | N1: Nº atributos | O1: Ficha revisada | P1: Comentarios del equipo
A2: M-01 | B2: Unidad de negocio | C2: Empresas del grupo que facturan y registran. | D2: 2.1 Organización y contabilidad | E2: 0 | F2: cuit | G2: — (raíz) | H2: Parcial | I2: Definición con Administración: estructura societaria, CUIT, moneda funcional y plan de cuentas de cada sociedad. | J2: Administración y Finanzas | K2: Administración y Finanzas | L2: MD-01 Sociedad | M2: — | N2: 7 | O2: Pendiente
A3: M-02 | B3: Centro de costo | C3: Centros de costo de la unidad de negocio. | D3: 2.1 Organización y contabilidad | E3: 1 | F3: codigo | G3: M-01 | H3: No (nuevo en el modelo) | I3: Documento "Modelo de sistema basado en Master Data y Operativos" (09/09/2026) | J3: Administración y Finanzas | K3: Administración y Finanzas | L3: — (nuevo en el modelo) | M3: — | N3: 5 | O3: Pendiente
A4: M-03 | B4: Cuenta objeto | C4: Cuentas y objetos de imputación: cuentas del plan y el objeto de costo que se abre por cada operativo. | D4: 2.1 Organización y contabilidad | E4: 1 | F4: codigo | G4: M-02 | H4: Parcial / Sí | I4: Definición previa Nº 7 (parte 1): plan de cuentas por sociedad con marca de imputabilidad y exigencia de centro de costo. | Definición previa Nº 7 (parte 2): estructura de centros más el objeto de costo de tipo 'operativo' (construcción nueva, se abre automático con TX-03). | J4: Administración y Finanzas | K4: Administración y Finanzas | L4: MD-30 Plan de cuentas + MD-31 Centro y objeto de costo | M4: TX-08 · TX-42 | N4: 5 | O4: Pendiente
A5: M-04 | B5: Tipos de comprobantes | C5: Comprobantes que emite el sistema y su imputación por defecto. | D5: 2.1 Organización y contabilidad | E5: 1 | F5: codigo | G5: M-01 · M-02 · M-03 | H5: Sí | I5: Migración desde la configuración de comprobantes actual más las plantillas de remito de la carpeta compartida. | J5: Administración y Finanzas | K5: Administración y Finanzas | L5: MD-33 Comprobante y numeración | M5: — | N5: 6 | O5: Pendiente
A6: M-05 | B6: Áreas | C6: Áreas de la organización y los puestos de trabajo que dependen de ellas. La dotación propia se planifica por puesto (rol) y cantidad, nunca por persona: el puesto es el recurso; el legajo (28) se asigna en la ejecución. | D6: 2.1 Organización y contabilidad | E6: 0 | F6: codigo | G6: M-01 | H6: No | I6: Relevamiento de RRHH y Operaciones. La matriz de reemplazo es construcción nueva. | J6: RRHH | K6: RRHH | L6: MD-24 Puesto | M6: TX-18 | N6: 9 | O6: Pendiente
A7: M-06 | B7: Clientes / Proveedores | C7: Terceros con los que operamos: un CUIT, uno o varios roles (cliente, proveedor). | D7: 2.2 Clientes, proveedores y terceros | E7: 1 | F7: cuit | G7: M-01 | H7: Sí | I7: Migración desde los sistemas actuales con deduplicación por CUIT y resolución manual de conflictos de razón social. | Migración desde el registro de proveedores actual, que ya tiene procedimiento de alta y evaluación. | Migración desde el padrón de transportistas del sistema de logística más el registro de sanciones que hoy vive en correos y actas. La flota propia se marca como interna. | J7: Comercial · Compras | K7: Comercial · Compras | L7: MD-04 Cliente + MD-05 Proveedor + MD-21 Transportista | M7: TX-01 · TX-02 · TX-12 · TX-21 · TX-23.3 · TX-29 · TX-37 · TX-41 | N7: 10 | O7: Pendiente
A8: M-07 | B8: Productos | C8: Cada producto que se descarga, transporta o almacena. | D8: 2.3 Productos y condiciones de mercadería | E8: 0 | F8: codigo | G8: — (raíz) | H8: Parcial / Sí | I8: Migración desde la clasificación actual de artículos, con la merma teórica que hoy figura en los contratos. | Migración desde el maestro de artículos actual, con revisión de Calidad de presentaciones, densidad y muestreo. v2: se agrega el régimen regulatorio (RENPRE / RENAR) que hoy se verifica a mano. | J8: Operaciones · Calidad | K8: Operaciones · Calidad | L8: MD-13 Familia de producto + MD-14 Producto | M8: TX-01 · TX-13 · TX-23.2 · TX-23.3 · TX-37 · TX-42 | N8: 17 | O8: Pendiente
A9: M-08 | B9: Buques | C9: Cada buque: solo sus datos propios (la agencia es del arribo, en el LineUp). | D9: 2.5 Buques y transporte | E9: 0 | F9: numero_imo | G9: — (raíz) | H9: No | I9: Construcción desde la planilla del LineUp de los últimos 24 meses, con búsqueda y validación del IMO de cada buque. | J9: Operaciones Portuarias | K9: Operaciones Portuarias | L9: MD-16 Buque | M9: TX-01 · TX-09 · TX-16 · TX-24 · TX-31 | N9: 7 | O9: Pendiente
A10: M-09 | B10: Plantas | C10: Plantas propias, satélites, alquiladas, puertos y terminales. | D10: 2.4 Infraestructura | E10: 1 | F10: codigo | G10: M-01 · M-02 | H10: Parcial | I10: Relevamiento con Operaciones: plantas propias 1 y 2, satélites (Usina, AFA/Comirsa, GAP, MTR) y puerto, con distancia y costo de almacenaje medidos. v2.2: se agrega el tipo "puerto / terminal externa" para que MD-00 pueda referenciar Timbúes, PGSM, Arroyo Seco, Necochea, Ramallo, Villa Constitución y AES (Decisión D-1, hoja 6). | J10: Operaciones | K10: Operaciones | L10: MD-02 Planta y sitio | M10: TX-08 · TX-22 · TX-23.5 · TX-23.6 · TX-29 · TX-30 | N10: 16 | O10: Pendiente
A11: M-10 | B11: Depósitos | C11: Galpones, depósitos y parques de tanques, con sus celdas y boxes (detalle en 10a). | D11: 2.4 Infraestructura | E11: 2 | F11: codigo | G11: M-09 | H11: Parcial | I11: Definición previa Nº 3 (parte 1): inventario de depósitos propios, satélites, de terceros y Timbúes, con habilitaciones aduaneras (incl. provisorio de Comirsa) y regulatorias (RENPRE / RENAR) y sus vencimientos. | J11: Depósitos | K11: Depósitos | L11: MD-18 Depósito | M11: TX-06 · TX-11 · TX-12 · TX-13 · TX-20 · TX-23 · TX-23.1 · TX-23.2 · TX-23.4 · TX-23.5 · TX-23.6 · TX-34 | N11: 14 | O11: Pendiente
A12: M-10a | B12: Celdas · boxes · tanques (detalle de Depósitos) | C12: Cada celda, box o tanque del depósito con su capacidad. Es el detalle "celdas y capacidad / boxes y capacidad" del maestro 10. | D12: 2.4 Infraestructura | E12: 3 | F12: codigo | G12: M-10 | H12: No | I12: Definición previa Nº 3 (parte 2): inventario físico de celdas, boxes y tanques con capacidad y método de recepción (incl. fosa y noria). Es la carga nueva más importante del modelo: sin ubicación no hay stock por lote (TX-37). | J12: Depósitos | K12: Depósitos | L12: MD-19 Ubicación (celda · box · tanque) | M12: TX-11 · TX-23 · TX-23.4 · TX-23.7 · TX-23.8 · TX-23.9 · TX-28 · TX-34 · TX-35 · TX-37 · TX-38 | N12: 12 | O12: Pendiente
A13: M-11 | B13: Transporte | C13: Unidades de transporte (camión, batea, cisterna, barcaza) propias o de terceros. | D13: 2.5 Buques y transporte | E13: 2 | F13: codigo | G13: M-06 | H13: Sí | I13: Migración desde credenciales y checklists de portería, con la tara certificada desde los certificados vigentes. | J13: Logística | K13: Logística | L13: MD-23 Unidad de transporte | M13: TX-21 · TX-29 · TX-30 · TX-32 | N13: 14 | O13: Pendiente
... A32: M-30 | B32: Insumos y repuestos | C32: Repuestos e insumos del pañol. | D32: 2.6 Maquinaria, personal e insumos | E32: 1 | F32: codigo | G32: M-09 | H32: No | I32: Relevamiento físico del pañol con criticidad, stock mínimo y proveedor habitual por repuesto. | J32: Mantenimiento · Pañol | K32: Mantenimiento · Pañol | L32: MD-29 Repuesto de pañol | M32: — | N32: 14 | O32: Pendiente
A33: M-31 | B33: Cupos de ingreso | C33: Cuadro de cupos de ingreso por camión (no buque): fecha, planta, cliente, producto, camiones y toneladas autorizadas. Entrada de la planificación para servicios sin buque. Administración centralizada en dos tramos: Comercial carga el cupo (cliente, producto, contrato, día, camiones, toneladas) y Tráfico — Portería lo completa (turno, portón, confirmación de planta). | D33: 2.8 Planificación portuaria y de arribos | E33: 3 | F33: codigo | G33: M-09 · M-06 · M-07 · M-16 | H33: Parcial (planilla de cupos) | I33: Carga inicial desde la planilla de cupos vigente; después alta diaria por Comercial y completado por Tráfico — Portería. | J33: Comercial / Backoffice (tramo comercial) · Tráfico — Portería y Balanza (tramo de portería) | K33: Cada rol autoriza su tramo (vigente al guardar) | L33: — (nuevo en el modelo; faltaba en v3.0) | M33: TX-01 · TX-04 · TX-21 · TX-22 · TX-32 | N33: 15 | O33: Pendiente | P33: Incorporado en v3.1: estaba en el FD v1.0 y en el simulador, pero no en este Excel.
A34: M-32 | B34: Arribos ferroviarios | C34: Programa de trenes: formaciones que arriban a la playa de vías con mercadería del cliente (ingreso) o para cargar (egreso). Es la entrada de los servicios sin buque que llegan por ferrocarril; se administra en forma centralizada con dos tramos: comercial (Comercial / Backoffice) y operativo (Logística). | D34: 2.8 Planificación portuaria y de arribos | E34: 3 | F34: codigo | G34: M-09 · M-06 · M-07 · M-16 | H34: No (hoy avisos por correo / teléfono del operador) | I34: Construcción desde los avisos de los operadores ferroviarios (BCyL, NCA); alta por Comercial y completado por Logística. | J34: Comercial / Backoffice (tramo comercial) · Logística (tramo operativo) | K34: Cada rol autoriza su tramo (vigente al guardar) | L34: — (nuevo en la revisión 15/09/2026) | M34: TX-43 · TX-21 · TX-22 · TX-23 | N34: 17 | O34: Pendiente | P34: Revisión 15/09/2026: la mercadería también arriba por ferrocarril.
A35: M-33 | B35: Régimen de turnos | C35: Turnos operativos del día y su duración (por defecto 4 turnos de 6 h). Parametriza la duración del turno: la cantidad de turnos planificados determina la duración del operativo (ETC = ETB + turnos × duración). 19 Calendario y turnos clasifica cada día (hábil / inhábil / feriado) sobre estos turnos. | D35: 2.9 Parámetros generales | E35: 0 | F35: codigo | G35: — (raíz) | H35: Parcial (régimen escrito en los convenios; hoy 3 × 8 h) | I35: Definición previa Nº 13: RRHH y Operaciones fijan los 4 turnos de 6 h (T1 06–12 · T2 12–18 · T3 18–24 · T4 00–06) y el inicio del día operativo. | J35: RRHH · Operaciones | K35: RRHH y Planta (cadena de autorización) | L35: — (nuevo en la revisión 15/09/2026) | M35: TX-15 · TX-18 · TX-25 · TX-26 | N35: 8 | O35: Pendiente | P35: Revisión 15/09/2026: turnos de 6 h parametrizados; la cantidad de turnos define la duración del operativo.
A36: M-34 | B36: Métodos seguros | C36: Procedimiento y documentación que avalan la forma segura de gestionar un recurso u operación (método seguro, MS). Cada recurso de la master data referencia el o los MS que lo avalan; un MS vencido deja al recurso sin disponibilidad para planificar (o lo deja con observación, según la acción declarada al vencer). | D36: 2.10 Seguridad y métodos seguros | E36: 0 | F36: codigo | G36: M-05 | H36: Parcial (procedimientos de SyH en papel / carpeta) | I36: Definición previa Nº 14: Seguridad e Higiene inventaría los procedimientos vigentes con tipo, documento, versión, vencimiento y acción al vencer, y los asocia a cada recurso. | J36: Seguridad e Higiene | K36: Seguridad e Higiene (cadena de autorización) | L36: — (nuevo en la revisión 15/09/2026) | M36: TX-14 · TX-18 · TX-21 · TX-22 · TX-23 | N36: 12 | O36: Pendiente | P36: Revisión 15/09/2026: atributo "Método seguro" en la master data.

Sheet 2-Atributos
A1: M | B1: Entidad | C1: Nº | D1: Atributo | E1: Tipo de dato | F1: Obligatorio | G1: Dominio de valores / validación | H1: ¿Parámetro administrable? | I1: Regla / observación | J1: Origen | K1: Carácter | L1: Equivalente v2.2 | M1: Revisión en sesión | N1: Comentarios del equipo
A2: M-01 | B2: Unidad de negocio | C2: 1 | D2: codigo | E2: Código (8) | F2: Sí | G2: — | H2: No | I2: — | J2: Modelo | K2: propio | L2: MD-01.codigo | M2: Pendiente
A3: M-01 | B3: Unidad de negocio | C3: 2 | D3: nombre | E3: Texto (120) | F3: Sí | G3: — | H3: No | I3: — | J3: Modelo | K3: propio | L3: MD-01.razon_social | M3: Pendiente
A4: M-01 | B4: Unidad de negocio | C4: 3 | D4: cuit | E4: Código (11) | F4: Sí | G4: 11 dígitos | H4: No | I4: — | J4: Modelo | K4: propio | L4: MD-01.cuit | M4: Pendiente
A5: M-01 | B5: Unidad de negocio | C5: 4 | D5: grupo_economico | E5: Texto (80) | F5: No | G5: — | H5: No | I5: — | J5: Modelo | K5: propio | L5: — (nuevo) | M5: Pendiente
A6: M-01 | B6: Unidad de negocio | C6: 5 | D6: moneda_funcional | E6: Ref. M-18 | F6: Sí | G6: — | H6: No | I6: — | J6: Modelo | K6: propio | L6: MD-01.moneda_funcional | M6: Pendiente
A7: M-01 | B7: Unidad de negocio | C7: 6 | D7: plan_cuentas | E7: Texto (40) | F7: No | G7: — | H7: No | I7: Referencia al plan de cuentas (las cuentas viven en 3 Cuenta objeto) | J7: Modelo | K7: propio | L7: MD-01.plan_cuentas | M7: Pendiente
A8: M-01 | B8: Unidad de negocio | C8: 7 | D8: estado | E8: Enumerado | F8: Sí | G8: activa · inactiva | H8: No | I8: — | J8: Modelo | K8: propio | L8: MD-01.estado | M8: Pendiente
A9: M-02 | B9: Centro de costo | C9: 1 | D9: codigo | E9: Código (12) | F9: Sí | G9: — | H9: No | I9: — | J9: Modelo | K9: propio | L9: — (nuevo) | M9: Pendiente
A10: M-02 | B10: Centro de costo | C10: 2 | D10: nombre | E10: Texto (80) | F10: Sí | G10: — | H10: No | I10: — | J10: Modelo | K10: propio | L10: — (nuevo) | M10: Pendiente
A11: M-02 | B11: Centro de costo | C11: 3 | D11: unidad_negocio | E11: Ref. M-01 | F11: Sí | G11: — | H11: No | I11: — | J11: Modelo | K11: propio | L11: — (nuevo) | M11: Pendiente
A12: M-02 | B12: Centro de costo | C12: 4 | D12: tipo | E12: Enumerado | F12: Sí | G12: operativo · administrativo · comercial · mantenimiento | H12: No | I12: — | J12: Modelo | K12: propio | L12: — (nuevo) | M12: Pendiente
A13: M-02 | B13: Centro de costo | C13: 5 | D13: estado | E13: Enumerado | F13: Sí | G13: activo · inactivo | H13: No | I13: — | J13: Modelo | K13: propio | L13: — (nuevo) | M13: Pendiente
... A375: M-34 | B375: Métodos seguros | C375: 12 | D375: estado | E375: Enumerado | F375: Sí | G375: vigente · en revisión · vencido · reemplazado | H375: No | I375: — | J375: Revisión 15/09/2026 | K375: propio | L375: — (nuevo) | M375: Pendiente

Sheet 3-Auditoría y ciclo de vida
A1: Atributo | B1: Tipo | C1: Obligatorio | D1: Dominio de valores | E1: Regla
A2: estado_registro | B2: Enumerado | C2: Sí | D2: borrador · en validación · en autorización · vigente · publicada · suspendida · dada de baja | E2: Lo maneja el motor de workflow, no el usuario. Nada se borra: la baja solo procede sin movimientos.
A3: creado_por / creado_el | B3: Ref. usuario · Fecha y hora | C3: Sí | D3: — | E3: Solicitante y momento de la solicitud.
A4: validado_por / validado_el | B4: Ref. usuario · Fecha y hora | C4: Condicional | D4: — | E4: Curador del dominio: controla consistencia, documentación y duplicados. Obligatorio para pasar a autorización.
A5: autorizado_por / autorizado_el | B5: Ref. usuario · Fecha y hora | C5: Condicional | D5: — | E5: El autorizante no puede ser el solicitante: el sistema lo impide (control por oposición).
A6: version | B6: Entero | C6: Sí | D6: ≥ 1 | E6: Se incrementa con cada cambio autorizado; la versión anterior queda cerrada y legible.
A7: origen | B7: Enumerado | C7: Sí | D7: manual · migración · integración · alta provisoria | E7: Permite medir las altas fuera del circuito.
A8: vence_el | B8: Fecha | C8: Condicional | D8: — | E8: Solo altas provisorias: 72 horas para regularizar o suspender.
A10: Ciclo de vida del registro
A11: Estado | B11: Qué pasa | C11: Regla
A12: 1 Borrador | B12: Cualquier solicitante del dominio completa el formulario. | C12: No avanza con un obligatorio vacío ni una referencia inexistente.
A13: 2 En validación | B13: El curador del dominio controla consistencia, documentación, vencimientos y duplicados. | C13: La devolución exige motivo, que queda en la traza.
A14: 3 En autorización | B14: El autorizante del dominio aprueba o rechaza. | C14: Para entidades con impacto económico la autorización es nominal y no delegable. Autorizante ≠ solicitante.
A15: 4 Vigente | B15: Se activa desde su fecha de vigencia y cierra la versión anterior. | C15: Una transacción vieja se lee con el parámetro que regía cuando ocurrió: sin retroactividad.
A16: 5 Publicada | B16: El maestro publica el alta o el cambio y los módulos que lo consumen lo reciben. | C16: Ningún módulo mantiene copia editable propia.
A17: 6 Suspendida / baja | B17: El dueño del dominio suspende con autorización. | C17: El vencimiento de un atributo con fecha suspende automáticamente. La baja solo sin movimientos.

Sheet 4-Convenciones
A1: Nº | B1: Convención | C1: Qué exige
A2: CV-1 | B2: Un solo origen | C2: Cada entidad tiene una sola definición para todo el grupo; los conflictos los resuelve el comité de datos.
A3: CV-2 | B3: Clave doble | C3: Clave primaria subrogada (interna, estable, nunca se reutiliza) + clave natural declarada (CUIT, patente, IMO, código) para detectar duplicados.
A4: CV-3 | B4: Sin relleno | C4: Un obligatorio vacío impide avanzar; prohibido '0', 'S/D' o defaults que oculten la falta. Si el dato no existe, queda en borrador.
A5: CV-4 | B5: Vencimiento con consecuencia | C5: Toda fecha de vencimiento declara qué hace el sistema al vencer: suspender, bloquear una transacción concreta o alertar. Sin consecuencia declarada, no se carga.
A6: CV-5 | B6: Vigencia y versionado | C6: Los parámetros económicos (tarifas, contratos, costos) se versionan con vigencia futura; no existe la modificación retroactiva.
A7: CV-6 | B7: Referencia, no texto | C7: Cuando un atributo apunta a otro maestro es una referencia con integridad, nunca texto libre. El texto libre queda solo en 'observación' y fuera de reglas e indicadores.
A8: CV-7 | B8: Unidades explícitas | C8: Toda magnitud declara su unidad en el modelo (tn, tn/h, camiones/h, km, días); la conversión es del sistema.
A9: CV-8 | B9: Estado, no borrado | C9: Nada se elimina: el ciclo de vida gobierna. Los códigos no se reutilizan al dar de baja.
A10: CV-9 | B10: Atributos propios del objeto | C10: La master data se construye con información propia del objeto. Lo que depende de la ocasión (la agencia que opera un buque en un arribo, el producto que hoy ocupa una celda) no es atributo del maestro: vive en el LineUp, el Operativo o el Contrato. Lo que el sistema deriva de las transacciones (ocupación, horómetro, homologado) es calculado y no se carga a mano.

Sheet 5-Orden de carga
A1: Nivel | B1: Maestros | C1: Qué se hace | D1: Esfuerzo y bloqueo
A2: 0 | B2: M-01 Unidad de negocio · M-05 Áreas · M-07 Productos · M-08 Buques · M-14 Tipos de servicios · M-18 Monedas y cotizaciones · M-20 Tolerancias · M-21 Agencia marítima / Armador · M-22 Despachante de aduana · M-27 Choferes · M-29 Causas de demora · M-33 Régimen de turnos · M-34 Métodos seguros | C2: Sin dependencias: catálogos, parámetros y objetos raíz. El régimen de turnos y el catálogo de métodos seguros se cargan primero porque los demás maestros los referencian. | D2: 1 a 2 semanas
A3: 1 | B3: M-02 Centro de costo · M-03 Cuenta objeto · M-04 Tipos de comprobantes · M-06 Clientes / Proveedores · M-09 Plantas · M-19 Calendario y turnos · M-23 Matriz de calidad · M-24 Matriz de compatibilidad · M-25 Muelles · M-30 Insumos y repuestos | C3: Dependen solo del nivel 0. M-19 Calendario referencia el régimen de turnos (M-33). | D3: 3 a 4 semanas
A4: 2 | B4: M-10 Depósitos · M-11 Transporte · M-12 Maquinaria · M-13 Personal contratado · M-15 Tarifas · M-16 Contratos · M-17 LineUp · M-26 Balanzas · M-28 Personal propio | C4: Maestros que controlan la operación: exigen definiciones previas del negocio y su método seguro vigente (M-34). | D4: 3 a 4 semanas
A5: 3 | B5: M-10a Celdas · boxes · tanques (detalle de Depósitos) · M-31 Cupos de ingreso · M-32 Arribos ferroviarios | C5: Inventario físico de celdas, boxes y tanques; programas de cupos y arribos ferroviarios (dependen del contrato y se administran por tramos). | D5: 2 a 3 semanas de relevamiento

Sheet 6-Definiciones previas
A1: Nº | B1: Definición | C1: Responsable | D1: Bloquea | E1: Qué hay que definir | F1: Revisión en sesión | G1: Comentarios del equipo
A2: Nº 1 | B2: El contrato como parámetro | C2: Comercial | D2: M-16 | E2: Ritmo, tolerancia, merma, volumen comprometido, tope de cupos y espacio de cada contrato vigente. Sin estos valores el contrato no pasa a vigente. v2: agrega la antelación del aviso (SLA 15–30 días), el alcance por defecto y la condición aduanera prevista. | F2: Pendiente
A3: Nº 2 | B3: Capacidad de cada balanza | C3: Tráfico · Balanza | D3: M-26 · M-20 (tolerancia 4 %) | E3: Medir tn/h, camiones/h y disponibilidad por banda de B1, B2, B3 (zona de puerto), balanza de depósito y fiscal de puerto, y declarar cuál prevalece en la conciliación. v2: fijar la cola máxima que dispara la derivación por congestión. | F3: Pendiente
A4: Nº 3 | B4: Inventario de ubicaciones | C4: Depósito | D4: M-10 · M-10a | E4: Relevamiento físico de depósitos, celdas, boxes y tanques con capacidad y método de recepción. Sin ubicación no hay trazabilidad por lote. v2: incluir fosa y noria, producto asignado y ocupación inicial por box. | F4: Pendiente
A5: Nº 4 | B5: Catálogo de causas de demora | C5: Operaciones · Calidad | D5: M-29 | E5: Lista cerrada con categoría, imputable y efecto sobre el ritmo contractual. v2: incorporar congestión de balanza, recepción lenta en depósito, desvío logístico (GPS) y avería / secuencia de bodegas del buque. | F5: Pendiente
A6: Nº 5 | B6: Plan de cuentas y objeto operativo | C6: Contabilidad | D6: M-03 · M-03 | E6: Plan de cuentas por sociedad con el objeto de costo de tipo operativo: la precondición de la registración automática y del margen por operativo. | F6: Pendiente
A7: Nº 6 | B7: Dotación de manos de referencia | C7: Operaciones Portuarias | D7: M-07 | E7: Manos de referencia por producto sólido a granel, para planificar antes de la confirmación del capitán. | F7: Pendiente
A8: Nº 7 | B8: Tabla de tolerancias operativas | C8: Operaciones · Logística · Tráfico | D8: M-20 | E8: Por cada proceso controlado: parámetro, valor base, tolerancia de exceso/defecto y acción al exceder (bloquear · autorización nominal · alertar y registrar). Hoy son criterio del coordinador de turno; pasan a ser dato con traza de quién autoriza cada desvío. | F8: Pendiente
A9: Nº 8 | B9: Especificaciones de calidad por producto | C9: Calidad | D9: M-23 | E9: Por cada producto con muestreo: parámetros, valor nominal, banda de tolerancia, método de ensayo, frecuencia, punto de control y acción fuera de especificación (bloquear despacho · segregar · degradar). | F9: Pendiente
A10: Nº 9 | B10: Régimen regulatorio y habilitaciones | C10: Depósito · Calidad · Operaciones Portuarias | D10: M-07 · M-10 · M-21 · M-21 | E10: Por cada producto: si está alcanzado por RENPRE / RENAR. Por cada depósito: habilitaciones fiscal (incl. provisorio de Comirsa) y regulatorias con vencimiento y consecuencia. Catálogo de organismos externos y de documentos del expediente del buque con quién los emite y si bloquean el avance. Hoy la verificación es manual y no deja registro. | F10: Pendiente
A11: Nº 10 | B11: Fuentes y homologación del LineUp | C11: Operaciones Portuarias · Comercial | D11: M-17 · M-09 · M-08 · M-21 | E11: Qué LineUps se importan y con qué frecuencia (agencias, CGPSN, terminales de terceros), qué puertos y categorías de carga interesan (¿todo el río o solo fertilizantes y buques con potencial TyS?), quién es el curador que homologa buque / cliente / producto dentro de las 72 h, la tolerancia de variación de ETA que dispara alerta (M-20) y la regla de conflicto cuando dos fuentes informan tonelajes o fechas distintos (hoy: "REVISAR" en la columna de observaciones). Hoy la consolidación es manual (hoja "Integrado") y no queda trazada. | F11: Pendiente
A12: Nº 11 | B12: Catálogo de tipos de servicio (M-14) | C12: Comercial · Operaciones | D12: M-14 · M-15 · M-16 | E12: Lista de servicios simples (DESC, TRA, ALM…) y combinados, con componentes, origen (LineUp / solicitud), recursos que consume, controles obligatorios y etapas del Operativo que aplican. Sin esta lista no hay Operativo ni tarifa. | F12: Pendiente
A13: Nº 12 | B13: Criterio de destino y matriz de manos | C13: Planificación · Depósitos · Operaciones | D13: M-07 · M-09 · M-10 · M-25 | E13: Prioridad planta propia → satélite → alquilada; costo de flete y almacenaje de referencia por planta (M-09 ★); tn por mano y turno por producto (M-07 ★) y su variante por puerto / muelle / calidad. | F13: Pendiente
... A19: Nº 18 | B19: Recursos por categoría: manos, puestos y choferes | C19: RRHH · Operaciones · Logística | D19: M-13 (composicion_roles) · M-05 (puestos) · M-27 | E19: Composición por roles de cada categoría de mano; dotación mínima y costo horario por puesto; universo de choferes habilitados (licencia, credencial, ART). Se planifica por cantidad, nunca por nombre. | F19: Pendiente
A21: Decisiones por maestro — abiertas (heredadas del v2.2, remapeadas) y tomadas por el modelo
A22: Código | B22: Maestro | C22: Decisión | D22: Opciones | E22: Recomendación / decisión | F22: Impacto si no se decide | G22: Estado
A23: D-1 | B23: M-17 LineUp portuario | C23: Dónde viven los puertos externos | D23: (a) Ampliar M-09 con tipo "puerto / terminal externa" · (b) Catálogo nuevo MD-38 Puerto | E23: (a): M-09 ya tiene satélites y puerto; un tipo más no rompe nada y evita otro maestro. | F23: M-17 no puede referenciar puerto (CV-6) y queda como texto. | G23: Abierta
A24: D-2 | B24: M-17 LineUp portuario | C24: Operador de terminal (TYS, PTP, MTR, CASPORT) | D24: (a) Enumerado en M-17 · (b) Ref. M-06 Proveedor · (c) Ref. M-21 Organismo externo | E24: (a) para arrancar; migrar a referencia si se necesita facturar / contratar con ellos. | F24: Bajo. | G24: Abierta
A25: D-3 | B25: M-17 LineUp portuario | C25: Alcance de la importación | D25: (a) Todo el LineUp del río · (b) Solo puertos de interés y familia fertilizantes · (c) Todo, con alcance_geografico = fuera de interés para lo demás | E25: (c): conserva la visión completa del río para IA y competencia sin cargar de seguimiento a Operaciones. | F25: Volumen y ruido en el panel. | G25: Abierta
A26: D-4 | B26: M-17 LineUp portuario | C26: Curador y frecuencia | D26: ¿Quién importa y homologa cada día? ¿Una vez (mañana) o al recibir cada LineUp? | E26: Operaciones Portuarias, una corrida diaria antes de la reunión de las 14:00 + eventos ad hoc. | F26: Sin dueño, el maestro envejece como el Excel actual. | G26: Abierta
A27: D-5 | B27: M-17 LineUp portuario | C27: Prevalencia entre fuentes | D27: Aviso del cliente > LineUp de agencia > CGPSN > terminal tercera, o por antigüedad de la versión | E27: Aviso del cliente prevalece en cliente / producto / tonelaje; agencia prevalece en ETA / ETB / ETC. | F27: Las discrepancias siguen resolviéndose "a criterio". | G27: Abierta
A28: D-6 | B28: M-17 LineUp portuario | C28: Tolerancia de variación de ETA (AL-2) | D28: Horas que disparan la alerta | E28: 24 h como valor inicial en M-20; ajustar con datos. | F28: Alertas en exceso o en defecto. | G28: Abierta
A29: D-7 | B29: M-17 LineUp portuario | C29: Clave natural definitiva | D29: puerto + buque + ETA (fecha) + cliente + producto vs. incluir agencia | E29: La propuesta; agencia no, porque puede cambiar. | F29: Duplicados o fusiones indebidas en la importación. | G29: Abierta
A30: D-8 | B30: M-06 Clientes / Proveedores | C30: Un solo maestro de terceros | D30: (a) Clientes y proveedores separados (v2.2) · (b) Unificados con tipo y rubro | E30: (b) DECIDIDO POR EL MODELO: un CUIT, un registro; tipo cliente / proveedor / ambos y rubro múltiple (importador, trader, transporte, estiba, rental…). Los transportistas son proveedores de rubro transporte. | F30: — | G30: Decidida (modelo)
A31: D-9 | B31: M-14 Tipos de servicios | C31: Modalidad de operación | D31: (a) Maestro MD-12 Modalidad (v2.2) · (b) Atributo del contrato / operativo | E31: (b) DECIDIDO POR EL MODELO: la modalidad (DIRECTO · DEPOSITO · SATELITE · FISCAL) es un atributo de M-16 Contratos (modalidad_por_defecto) y del Operativo; el tipo de servicio (M-14) define componentes y recursos. | F31: — | G31: Decidida (modelo)
A32: D-10 | B32: M-21 Agencia / Armador | C32: Organismos y documentos exigidos | D32: (a) Maestros MD-36 / MD-37 (v2.2) · (b) Reglas del circuito | E32: (b) DECIDIDO POR EL MODELO: la documentación del buque (BL, manifiesto, plan de bodegas, despacho, certificado de calidad, habilitación aduanera) y el plazo ante Aduana (20 días) son reglas del proceso; el faltante se reclama a la agencia (M-21). | F32: Si en la práctica la lista de documentos cambia por cliente / régimen, revisar si conviene un catálogo parametrizable. | G32: Decidida (modelo) — revisar en sesión
A33: D-11 | B33: M-07 Productos | C33: Familia como atributo | D33: (a) Maestro MD-13 Familia (v2.2) · (b) Enumerado en el producto | E33: (b) DECIDIDO POR EL MODELO: familia es un enumerado del producto; la merma teórica pasa a ser atributo del producto (antes de la familia). | F33: — | G33: Decidida (modelo)
... A40: D-18 | B40: M-34 Métodos seguros | C40: Obligatoriedad del MS por maestro | D40: (a) Obligatorio en productos, depósitos, transporte, maquinaria, manos, tipos de servicio, muelles y balanzas; opcional en ubicaciones, puestos e insumos (adoptada) · (b) obligatorio en todos · (c) solo alerta, nunca bloquea | E40: (a): bloquea donde el riesgo es propio del recurso y no frena la carga inicial en los demás; (b) frena la migración; (c) no cumple "debe haber un procedimiento que avale la gestión". | F40: Recursos operando sin procedimiento vigente o migración frenada. | G40: Abierta

Sheet 7-Reglas por maestro
A1: Maestro | B1: Tipo | C1: Código | D1: Nombre de la regla | E1: Qué controla / qué hace | F1: Cuándo se aplica / quién la dispara | G1: Consecuencia o destinatario | H1: Parámetro (dónde se ajusta) | I1: Transacciones relacionadas | J1: Revisión en sesión | K1: Comentarios del equipo
A2: M-17 | B2: ABM | C2: ABM-1 | D2: Alta por aviso del cliente | E2: Crea la fila con nominado_a_tys = Sí, fuente = aviso del cliente, y la cruza con el LineUp del puerto: si el buque ya estaba, vincula en lugar de duplicar. | F2: Comercial / Operaciones en TX-01 | G2: Solicita quien registra el aviso; valida el curador de Operaciones Portuarias. | H2: — | I2: TX-01 · TX-02 · TX-09 · EV-01 · EV-09 · EV-16 · Dispara EV-01 si la información mínima está completa (TX-01 → TX-02 si falta). | J2: Pendiente
A3: M-17 | B3: ABM | C3: ABM-2 | D3: Alta / actualización por importación | E3: Parsea cada formato, normaliza, homologa por alias y genera una versión nueva de cada fila cambiada. Lo no homologable queda en alta provisoria (72 h). | F3: Importación diaria de los LineUps (agencias, CGPSN, terminales) | G3: El proceso automático es el solicitante; el curador homologa y autoriza en lote. | H3: — | I3: TX-01 · TX-02 · TX-09 · EV-01 · EV-09 · EV-16 · Nunca sobreescribe: cada import es una versión con fecha_version. | J3: Pendiente
A4: M-17 | B4: ABM | C4: ABM-3 | D4: Alta manual | E4: Formulario con los obligatorios; referencias, no texto. | F4: Operaciones Portuarias | G4: Solicitante ≠ autorizante. | H4: — | I4: TX-01 · TX-02 · TX-09 · EV-01 · EV-09 · EV-16 · Para buques que llegan por teléfono / WhatsApp y todavía no están en ningún LineUp. | J4: Pendiente
A5: M-17 | B5: ABM | C5: ABM-4 | D5: Modificación de fechas (ETA / ETB / ETC) | E5: Guarda el valor anterior y el nuevo; si la variación supera la tolerancia de M-20 emite la alerta AL-2 y recalcula la antelación (TX-03). | F5: Import · TX-09 (ETA actualizado) · agencia | G5: Automática; el cambio manual exige motivo. | H5: — | I5: TX-01 · TX-02 · TX-09 · EV-01 · EV-09 · EV-16 · Es el cambio más frecuente: la clave del modelo es que quede trazado. | J5: Pendiente
A6: M-17 | B6: ABM | C6: ABM-5 | D6: Homologación | E6: Reemplaza los textos de fuente por referencias (M-08, M-06, M-07, M-21); si el maestro no existe, abre su alta desde acá. | F6: Curador de Operaciones Portuarias | G6: Quien homologa no es quien importó. | H6: — | I6: TX-01 · TX-02 · TX-09 · EV-01 · EV-09 · EV-16 · Vencida la provisoria (72 h) la fila se suspende y no alimenta paneles. | J6: Pendiente
A7: M-17 | B7: ABM | C7: ABM-6 | D7: Cambio de estado | E7: EV-01 → confirmado · EV-09 → operando · EV-16 → finalizado. Manual: en rada, atracado, cancelado. | F7: Eventos del circuito | G7: Automático desde eventos. | H7: — | I7: TX-01 · TX-02 · TX-09 · EV-01 · EV-09 · EV-16 · Sin cierre manual del operativo la fila nunca queda "finalizado". | J7: Pendiente
A8: M-17 | B8: ABM | C8: ABM-7 | D8: Baja lógica | E8: Solo "cancelado" o "fuera de interés"; nada se borra (CV-8). Las filas finalizadas se archivan y alimentan la capa analítica (estadía, antelación, ETA vs. real). | F8: Curador, con autorización | G8: Autorizante ≠ solicitante. | H8: — | I8: TX-01 · TX-02 · TX-09 · EV-01 · EV-09 · EV-16 · El histórico es el insumo del caso de IA "ETA / atraque". | J8: Pendiente
A9: M-17 | B9: Validación | C9: VA-1 | D9: Clave natural única | E9: puerto + buque + fecha ETA + cliente + producto no puede repetirse entre filas vigentes. | F9: Alta e import | G9: Se vincula a la fila existente (nueva versión) en lugar de crear otra. | H9: — | I9: TX-01 · TX-02 | J9: Pendiente
A10: M-17 | B10: Validación | C10: VA-2 | D10: Secuencia de fechas | E10: eta ≤ etb ≤ etc; ninguna anterior a fecha_version − 30 días. | F10: Alta y modificación | G10: Fila en borrador con motivo; no alimenta paneles. | H10: — | I10: TX-01 · TX-02 | J10: Pendiente
A11: M-17 | B11: Validación | C11: VA-3 | D11: Tonelaje | E11: toneladas_nominadas > 0; toneladas_para_tys ≤ toneladas_nominadas. | F11: Alta y modificación | G11: Borrador ("sin TM"). | H11: — | I11: TX-01 · TX-02 | J11: Pendiente
A12: M-17 | B12: Validación | C12: VA-4 | D12: Referencias si es de TyS | E12: nominado_a_tys = Sí exige buque, cliente, producto y agencia como referencias (no texto) y toneladas_para_tys. | F12: Al registrar el aviso (TX-01) y al homologar | G12: No dispara EV-01; deriva a TX-02 (datos faltantes). | H12: — | I12: TX-01 · TX-02 | J12: Pendiente
A13: M-17 | B13: Validación | C13: VA-5 | D13: Sitio coherente con el puerto | E13: Si puerto es propio, sitio_atraque debe ser Ref. M-25 de esa planta. | F13: Alta y modificación | G13: Rechazo con motivo. | H13: — | I13: TX-01 · TX-02 | J13: Pendiente
... A59: Operativo | B59: Automatización | C59: A-PLANREAL | D59: Planificado vs. efectivamente realizado | E59: Al aprobar el plan se guarda la foto del plan inicial; cada orden adicional, liberación o excepción de Operaciones queda como ajuste; la ejecución registra lo utilizado por tarea. Comparativa plan inicial → vigente → realizado en el operativo, el fin de la ejecución y el cierre. | F59: EV-08 (foto) · OS de Operaciones (ajustes) · C-DOTACION / C3 / C-MAQUINARIA / C-BALANZA / C9 / D3 (realizado) | G59: EV-PLANREAL · KPI de desvío plan vs. real | H59: — | I59: TX-44 | J59: Pendiente

Sheet 8-Mapeo de fuentes
A1: Maestro | B1: Atributo destino | C1: Fuente 1 | D1: Columna / campo en fuente 1 | E1: Fuente 2 | F1: Columna / campo en fuente 2 | G1: Regla de transformación / homologación | H1: Revisión en sesión | I1: Comentarios del equipo
A2: M-17 | B2: puerto | C2: LINEUP.xlsx — formato agencia (Necochea · Ramallo · AES · Villa Constitución) | D2: PORT | E2: LINEUP.xlsx — formato PSN / CGPSN (Cs. Grales · Elevador · Arroyo · PGSM · Timbúes) | F2: Encabezado de la hoja (PUERTO SAN NICOLAS, TIMBUES…) | G2: Se resuelve contra M-09 por tabla de alias (ej. "SAN NICOLAS" → PSN). Columna equivalente en la hoja "Integrado": PUERTO. | H2: Pendiente
A3: M-17 | B3: sitio_atraque | C3: LINEUP.xlsx — formato agencia (Necochea · Ramallo · AES · Villa Constitución) | D3: BERTH | E3: LINEUP.xlsx — formato PSN / CGPSN (Cs. Grales · Elevador · Arroyo · PGSM · Timbúes) | F3: Subtítulo (Muelle Cargas Generales / Elevador) · SECTOR | G3: Puerto propio → Ref. M-25; externo → texto. Columna equivalente en la hoja "Integrado": SITIO DE ATRAQUE. | H3: Pendiente
A4: M-17 | B4: buque / buque_texto_fuente | C4: LINEUP.xlsx — formato agencia (Necochea · Ramallo · AES · Villa Constitución) | D4: VESSEL | E4: LINEUP.xlsx — formato PSN / CGPSN (Cs. Grales · Elevador · Arroyo · PGSM · Timbúes) | F4: BUQUE | G4: Normalizar (mayúsculas, sin "MV"/"MT", sin puntos) → buscar en M-08 por alias; si no existe, alta provisoria. Columna equivalente en la hoja "Integrado": BUQUE. | H4: Pendiente
A5: M-17 | B5: agencia | C5: LINEUP.xlsx — formato agencia (Necochea · Ramallo · AES · Villa Constitución) | D5: — (no viene) | E5: LINEUP.xlsx — formato PSN / CGPSN (Cs. Grales · Elevador · Arroyo · PGSM · Timbúes) | F5: AGENCIA (PTP, ISA, MARSA, AMI…) | G5: Ref. M-21 por alias. Vacía en la mayoría de los LineUps de terceros. Columna equivalente en la hoja "Integrado": AGENCIA. | H5: Pendiente
A6: M-17 | B6: operador | C6: LINEUP.xlsx — formato agencia (Necochea · Ramallo · AES · Villa Constitución) | D6: — (implícito en BERTH) | E6: LINEUP.xlsx — formato PSN / CGPSN (Cs. Grales · Elevador · Arroyo · PGSM · Timbúes) | F6: OPERADOR (TYS, PTP, MTR, CASPORT) | G6: Enumerado / catálogo (Decisión D-2). Columna equivalente en la hoja "Integrado": OPERADOR. | H6: Pendiente
A7: M-17 | B7: cliente / cliente_texto_fuente | C7: LINEUP.xlsx — formato agencia (Necochea · Ramallo · AES · Villa Constitución) | D7: SHIIPPER (a veces es el receiver) | E7: LINEUP.xlsx — formato PSN / CGPSN (Cs. Grales · Elevador · Arroyo · PGSM · Timbúes) | F7: CLIENTES | G7: Ref. M-06 por alias. Un buque con varios clientes = varias filas (así viene en PSN Cs. Grales). Columna equivalente en la hoja "Integrado": CLIENTE. | H7: Pendiente
A8: M-17 | B8: shipper | C8: LINEUP.xlsx — formato agencia (Necochea · Ramallo · AES · Villa Constitución) | D8: SHIIPPER | E8: LINEUP.xlsx — formato PSN / CGPSN (Cs. Grales · Elevador · Arroyo · PGSM · Timbúes) | F8: — | G8: Texto informativo. Columna equivalente en la hoja "Integrado": SHIPPER. | H8: Pendiente
A9: M-17 | B9: producto / producto_texto_fuente | C9: LINEUP.xlsx — formato agencia (Necochea · Ramallo · AES · Villa Constitución) | D9: CAT + CARGO (FERTILIZERS / MAP) | E9: LINEUP.xlsx — formato PSN / CGPSN (Cs. Grales · Elevador · Arroyo · PGSM · Timbúes) | F9: MATERIAL (MAP, DAP, UREA, TRIPLE, SMOP…) | G9: Ref. M-07 por alias; CAT → M-07 Familia. Alias no reconocido → alta provisoria. Columna equivalente en la hoja "Integrado": PRODUCTO. | H9: Pendiente
A10: M-17 | B10: tipo_operacion | C10: LINEUP.xlsx — formato agencia (Necochea · Ramallo · AES · Villa Constitución) | D10: OPS (DISCH · LOAD · WTG) | E10: LINEUP.xlsx — formato PSN / CGPSN (Cs. Grales · Elevador · Arroyo · PGSM · Timbúes) | F10: OPERACIÓN (DESCARGA · CARGA · TRASBORDO) | G10: Enumerado unificado: descarga · carga · trasbordo · espera · otro. Columna equivalente en la hoja "Integrado": TIPO. | H10: Pendiente
A11: M-17 | B11: toneladas_nominadas | C11: LINEUP.xlsx — formato agencia (Necochea · Ramallo · AES · Villa Constitución) | D11: QUANTITY | E11: LINEUP.xlsx — formato PSN / CGPSN (Cs. Grales · Elevador · Arroyo · PGSM · Timbúes) | F11: TONS. | G11: Decimal tn > 0; las filas de subtotal de la fuente se descartan en la importación. Columna equivalente en la hoja "Integrado": TONELADAS. | H11: Pendiente
A12: M-17 | B12: toneladas_para_tys · alcance_geografico | C12: LINEUP.xlsx — formato agencia (Necochea · Ramallo · AES · Villa Constitución) | D12: — | E12: LINEUP.xlsx — formato PSN / CGPSN (Cs. Grales · Elevador · Arroyo · PGSM · Timbúes) | F12: Hoja "Buques Ferti": matriz buque × terminal con leyenda de colores (solo SN · SN + upriver · en CGPSN sin agencia) | G12: La matriz se reemplaza por los dos atributos: la parte de TyS y el alcance geográfico. | H12: Pendiente
A13: M-17 | B13: origen · destino | C13: LINEUP.xlsx — formato agencia (Necochea · Ramallo · AES · Villa Constitución) | D13: ORIGIN · DESTINATION · AREA | E13: LINEUP.xlsx — formato PSN / CGPSN (Cs. Grales · Elevador · Arroyo · PGSM · Timbúes) | F13: — | G13: Texto informativo. Columna equivalente en la hoja "Integrado": ORIGEN · DESTINO. | H13: Pendiente
... A32: M-31 | B32: codigo · fecha · planta · cliente · producto · contrato · camiones · toneladas · tipo_movimiento · turno · porton · confirmacion_planta | C32: Planilla de cupos de Comercial | D32: Día, cliente, producto, camiones, tn | E32: Planilla de portería (Tráfico) | F32: Turno, portón | G32: Se unifican en un solo registro con dos tramos: comercial (Comercial) y de portería (Tráfico). | H32: Pendiente

Sheet 9-Tablero
A1: Maestro | B1: Nombre | C1: Nivel | D1: Atributos | E1: Atributos ★ (simulador) | F1: Atributos validados | G1: Atributos con cambios | H1: Reglas definidas | I1: Reglas validadas | J1: Ficha revisada | K1: Atributos revisión 15/09
A2: ='1-Fichas de entidades'!A2 | B2: ='1-Fichas de entidades'!B2 | C2: ='1-Fichas de entidades'!E2 | D2: =COUNTIF('2-Atributos'!$A:$A,A2) | E2: =COUNTIFS('2-Atributos'!$A:$A,A2,'2-Atributos'!$J:$J,"★ Simulador") | F2: =COUNTIFS('2-Atributos'!$A:$A,A2,'2-Atributos'!$M:$M,"Validado") | G2: =COUNTIFS('2-Atributos'!$A:$A,A2,'2-Atributos'!$M:$M,"Con cambios") | H2: =COUNTIF('7-Reglas por maestro'!$A:$A,A2) | I2: =COUNTIFS('7-Reglas por maestro'!$A:$A,A2,'7-Reglas por maestro'!$J:$J,"Validado") | J2: ='1-Fichas de entidades'!O2 | K2: =COUNTIFS('2-Atributos'!$A:$A,A2,'2-Atributos'!$J:$J,"Revisión 15/09/2026")
A3: ='1-Fichas de entidades'!A3 | B3: ='1-Fichas de entidades'!B3 | C3: ='1-Fichas de entidades'!E3 | D3: =COUNTIF('2-Atributos'!$A:$A,A3) | E3: =COUNTIFS('2-Atributos'!$A:$A,A3,'2-Atributos'!$J:$J,"★ Simulador") | F3: =COUNTIFS('2-Atributos'!$A:$A,A3,'2-Atributos'!$M:$M,"Validado") | G3: =COUNTIFS('2-Atributos'!$A:$A,A3,'2-Atributos'!$M:$M,"Con cambios") | H3: =COUNTIF('7-Reglas por maestro'!$A:$A,A3) | I3: =COUNTIFS('7-Reglas por maestro'!$A:$A,A3,'7-Reglas por maestro'!$J:$J,"Validado") | J3: ='1-Fichas de entidades'!O3 | K3: =COUNTIFS('2-Atributos'!$A:$A,A3,'2-Atributos'!$J:$J,"Revisión 15/09/2026")
A4: ='1-Fichas de entidades'!A4 | B4: ='1-Fichas de entidades'!B4 | C4: ='1-Fichas de entidades'!E4 | D4: =COUNTIF('2-Atributos'!$A:$A,A4) | E4: =COUNTIFS('2-Atributos'!$A:$A,A4,'2-Atributos'!$J:$J,"★ Simulador") | F4: =COUNTIFS('2-Atributos'!$A:$A,A4,'2-Atributos'!$M:$M,"Validado") | G4: =COUNTIFS('2-Atributos'!$A:$A,A4,'2-Atributos'!$M:$M,"Con cambios") | H4: =COUNTIF('7-Reglas por maestro'!$A:$A,A4) | I4: =COUNTIFS('7-Reglas por maestro'!$A:$A,A4,'7-Reglas por maestro'!$J:$J,"Validado") | J4: ='1-Fichas de entidades'!O4 | K4: =COUNTIFS('2-Atributos'!$A:$A,A4,'2-Atributos'!$J:$J,"Revisión 15/09/2026")
A5: ='1-Fichas de entidades'!A5 | B5: ='1-Fichas de entidades'!B5 | C5: ='1-Fichas de entidades'!E5 | D5: =COUNTIF('2-Atributos'!$A:$A,A5) | E5: =COUNTIFS('2-Atributos'!$A:$A,A5,'2-Atributos'!$J:$J,"★ Simulador") | F5: =COUNTIFS('2-Atributos'!$A:$A,A5,'2-Atributos'!$M:$M,"Validado") | G5: =COUNTIFS('2-Atributos'!$A:$A,A5,'2-Atributos'!$M:$M,"Con cambios") | H5: =COUNTIF('7-Reglas por maestro'!$A:$A,A5) | I5: =COUNTIFS('7-Reglas por maestro'!$A:$A,A5,'7-Reglas por maestro'!$J:$J,"Validado") | J5: ='1-Fichas de entidades'!O5 | K5: =COUNTIFS('2-Atributos'!$A:$A,A5,'2-Atributos'!$J:$J,"Revisión 15/09/2026")
A6: ='1-Fichas de entidades'!A6 | B6: ='1-Fichas de entidades'!B6 | C6: ='1-Fichas de entidades'!E6 | D6: =COUNTIF('2-Atributos'!$A:$A,A6) | E6: =COUNTIFS('2-Atributos'!$A:$A,A6,'2-Atributos'!$J:$J,"★ Simulador") | F6: =COUNTIFS('2-Atributos'!$A:$A,A6,'2-Atributos'!$M:$M,"Validado") | G6: =COUNTIFS('2-Atributos'!$A:$A,A6,'2-Atributos'!$M:$M,"Con cambios") | H6: =COUNTIF('7-Reglas por maestro'!$A:$A,A6) | I6: =COUNTIFS('7-Reglas por maestro'!$A:$A,A6,'7-Reglas por maestro'!$J:$J,"Validado") | J6: ='1-Fichas de entidades'!O6 | K6: =COUNTIFS('2-Atributos'!$A:$A,A6,'2-Atributos'!$J:$J,"Revisión 15/09/2026")
A7: ='1-Fichas de entidades'!A7 | B7: ='1-Fichas de entidades'!B7 | C7: ='1-Fichas de entidades'!E7 | D7: =COUNTIF('2-Atributos'!$A:$A,A7) | E7: =COUNTIFS('2-Atributos'!$A:$A,A7,'2-Atributos'!$J:$J,"★ Simulador") | F7: =COUNTIFS('2-Atributos'!$A:$A,A7,'2-Atributos'!$M:$M,"Validado") | G7: =COUNTIFS('2-Atributos'!$A:$A,A7,'2-Atributos'!$M:$M,"Con cambios") | H7: =COUNTIF('7-Reglas por maestro'!$A:$A,A7) | I7: =COUNTIFS('7-Reglas por maestro'!$A:$A,A7,'7-Reglas por maestro'!$J:$J,"Validado") | J7: ='1-Fichas de entidades'!O7 | K7: =COUNTIFS('2-Atributos'!$A:$A,A7,'2-Atributos'!$J:$J,"Revisión 15/09/2026")
A8: ='1-Fichas de entidades'!A8 | B8: ='1-Fichas de entidades'!B8 | C8: ='1-Fichas de entidades'!E8 | D8: =COUNTIF('2-Atributos'!$A:$A,A8) | E8: =COUNTIFS('2-Atributos'!$A:$A,A8,'2-Atributos'!$J:$J,"★ Simulador") | F8: =COUNTIFS('2-Atributos'!$A:$A,A8,'2-Atributos'!$M:$M,"Validado") | G8: =COUNTIFS('2-Atributos'!$A:$A,A8,'2-Atributos'!$M:$M,"Con cambios") | H8: =COUNTIF('7-Reglas por maestro'!$A:$A,A8) | I8: =COUNTIFS('7-Reglas por maestro'!$A:$A,A8,'7-Reglas por maestro'!$J:$J,"Validado") | J8: ='1-Fichas de entidades'!O8 | K8: =COUNTIFS('2-Atributos'!$A:$A,A8,'2-Atributos'!$J:$J,"Revisión 15/09/2026")
A9: ='1-Fichas de entidades'!A9 | B9: ='1-Fichas de entidades'!B9 | C9: ='1-Fichas de entidades'!E9 | D9: =COUNTIF('2-Atributos'!$A:$A,A9) | E9: =COUNTIFS('2-Atributos'!$A:$A,A9,'2-Atributos'!$J:$J,"★ Simulador") | F9: =COUNTIFS('2-Atributos'!$A:$A,A9,'2-Atributos'!$M:$M,"Validado") | G9: =COUNTIFS('2-Atributos'!$A:$A,A9,'2-Atributos'!$M:$M,"Con cambios") | H9: =COUNTIF('7-Reglas por maestro'!$A:$A,A9) | I9: =COUNTIFS('7-Reglas por maestro'!$A:$A,A9,'7-Reglas por maestro'!$J:$J,"Validado") | J9: ='1-Fichas de entidades'!O9 | K9: =COUNTIFS('2-Atributos'!$A:$A,A9,'2-Atributos'!$J:$J,"Revisión 15/09/2026")
A10: ='1-Fichas de entidades'!A10 | B10: ='1-Fichas de entidades'!B10 | C10: ='1-Fichas de entidades'!E10 | D10: =COUNTIF('2-Atributos'!$A:$A,A10) | E10: =COUNTIFS('2-Atributos'!$A:$A,A10,'2-Atributos'!$J:$J,"★ Simulador") | F10: =COUNTIFS('2-Atributos'!$A:$A,A10,'2-Atributos'!$M:$M,"Validado") | G10: =COUNTIFS('2-Atributos'!$A:$A,A10,'2-Atributos'!$M:$M,"Con cambios") | H10: =COUNTIF('7-Reglas por maestro'!$A:$A,A10) | I10: =COUNTIFS('7-Reglas por maestro'!$A:$A,A10,'7-Reglas por maestro'!$J:$J,"Validado") | J10: ='1-Fichas de entidades'!O10 | K10: =COUNTIFS('2-Atributos'!$A:$A,A10,'2-Atributos'!$J:$J,"Revisión 15/09/2026")
A11: ='1-Fichas de entidades'!A11 | B11: ='1-Fichas de entidades'!B11 | C11: ='1-Fichas de entidades'!E11 | D11: =COUNTIF('2-Atributos'!$A:$A,A11) | E11: =COUNTIFS('2-Atributos'!$A:$A,A11,'2-Atributos'!$J:$J,"★ Simulador") | F11: =COUNTIFS('2-Atributos'!$A:$A,A11,'2-Atributos'!$M:$M,"Validado") | G11: =COUNTIFS('2-Atributos'!$A:$A,A11,'2-Atributos'!$M:$M,"Con cambios") | H11: =COUNTIF('7-Reglas por maestro'!$A:$A,A11) | I11: =COUNTIFS('7-Reglas por maestro'!$A:$A,A11,'7-Reglas por maestro'!$J:$J,"Validado") | J11: ='1-Fichas de entidades'!O11 | K11: =COUNTIFS('2-Atributos'!$A:$A,A11,'2-Atributos'!$J:$J,"Revisión 15/09/2026")
A12: ='1-Fichas de entidades'!A12 | B12: ='1-Fichas de entidades'!B12 | C12: ='1-Fichas de entidades'!E12 | D12: =COUNTIF('2-Atributos'!$A:$A,A12) | E12: =COUNTIFS('2-Atributos'!$A:$A,A12,'2-Atributos'!$J:$J,"★ Simulador") | F12: =COUNTIFS('2-Atributos'!$A:$A,A12,'2-Atributos'!$M:$M,"Validado") | G12: =COUNTIFS('2-Atributos'!$A:$A,A12,'2-Atributos'!$M:$M,"Con cambios") | H12: =COUNTIF('7-Reglas por maestro'!$A:$A,A12) | I12: =COUNTIFS('7-Reglas por maestro'!$A:$A,A12,'7-Reglas por maestro'!$J:$J,"Validado") | J12: ='1-Fichas de entidades'!O12 | K12: =COUNTIFS('2-Atributos'!$A:$A,A12,'2-Atributos'!$J:$J,"Revisión 15/09/2026")
A13: ='1-Fichas de entidades'!A13 | B13: ='1-Fichas de entidades'!B13 | C13: ='1-Fichas de entidades'!E13 | D13: =COUNTIF('2-Atributos'!$A:$A,A13) | E13: =COUNTIFS('2-Atributos'!$A:$A,A13,'2-Atributos'!$J:$J,"★ Simulador") | F13: =COUNTIFS('2-Atributos'!$A:$A,A13,'2-Atributos'!$M:$M,"Validado") | G13: =COUNTIFS('2-Atributos'!$A:$A,A13,'2-Atributos'!$M:$M,"Con cambios") | H13: =COUNTIF('7-Reglas por maestro'!$A:$A,A13) | I13: =COUNTIFS('7-Reglas por maestro'!$A:$A,A13,'7-Reglas por maestro'!$J:$J,"Validado") | J13: ='1-Fichas de entidades'!O13 | K13: =COUNTIFS('2-Atributos'!$A:$A,A13,'2-Atributos'!$J:$J,"Revisión 15/09/2026")
... A36: ='1-Fichas de entidades'!A36 | B36: ='1-Fichas de entidades'!B36 | C36: ='1-Fichas de entidades'!E36 | D36: =COUNTIF('2-Atributos'!$A:$A,A36) | E36: =COUNTIFS('2-Atributos'!$A:$A,A36,'2-Atributos'!$J:$J,"★ Simulador") | F36: =COUNTIFS('2-Atributos'!$A:$A,A36,'2-Atributos'!$M:$M,"Validado") | G36: =COUNTIFS('2-Atributos'!$A:$A,A36,'2-Atributos'!$M:$M,"Con cambios") | H36: =COUNTIF('7-Reglas por maestro'!$A:$A,A36) | I36: =COUNTIFS('7-Reglas por maestro'!$A:$A,A36,'7-Reglas por maestro'!$J:$J,"Validado") | J36: ='1-Fichas de entidades'!O36 | K36: =COUNTIFS('2-Atributos'!$A:$A,A36,'2-Atributos'!$J:$J,"Revisión 15/09/2026")
A37: Total | D37: =SUM(D2:D36) | E37: =SUM(E2:E36) | F37: =SUM(F2:F36) | G37: =SUM(G2:G36) | H37: =SUM(H2:H36) | I37: =SUM(I2:I36) | K37: =SUM(K2:K36)
A39: Nota: "Reglas definidas" cuenta filas de la hoja 7 cuyo maestro coincide exactamente con el código; las reglas compartidas (ej. "M-09 · M-10 · M-10a" o "Todos") no se atribuyen a un maestro.

Sheet 0-Cruce v2.2 → Modelo
A1: Cruce: maestros del Excel v2.2 (MD-00..MD-37) → maestros del modelo (M-01..M-30)
A2: Lectura: cada maestro del Excel anterior alimenta a un maestro del modelo (o se absorbe como atributo / regla). Ámbar = fusión; gris = deja de ser maestro.
A4: Código v2.2 | B4: Maestro v2.2 | C4: Nivel v2.2 | D4: → Maestro del modelo | E4: Nombre en el modelo | F4: Qué pasó
A5: MD-00 | B5: LineUp portuario | C5: 1 | D5: M-17 | E5: LineUp | F5: Coincide; eta / etb / etc pasan a 3 atributos; puerto_terminal → puerto; operacion → tipo_operacion; estado_lineup → estado.
A6: MD-01 | B6: Sociedad | C6: 0 | D6: M-01 | E6: Unidad de negocio | F6: Coincide (atributos según el modelo).
A7: MD-02 | B7: Planta y sitio | C7: 1 | D7: M-09 | E7: Plantas | F7: Coincide; agrega localidad, CP, fecha de habilitación / vencimiento; costos de flete y almacenaje de referencia ★.
A8: MD-03 | B8: Calendario y turno | C8: 1 | D8: M-19 | E8: Calendario y turnos | F8: Coincide; hora_desde_hasta → hora_desde · hora_hasta.
A9: MD-04 | B9: Cliente | C9: 1 | D9: M-06 | E9: Clientes / Proveedores | F9: Se fusiona con MD-05 y MD-21 en M-06 (tipo cliente).
A10: MD-05 | B10: Proveedor | C10: 0 | D10: M-06 | E10: Clientes / Proveedores | F10: Se fusiona en M-06 (tipo proveedor, rubro estiba / rental / repuestos / laboratorio / personal eventual).
A11: MD-06 | B11: Agencia marítima y armador | C11: 0 | D11: M-21 | E11: Agencia marítima / Armador | F11: Coincide (atributos según el modelo).
A12: MD-07 | B12: Sindicato y empresa de estiba | C12: 1 | D12: M-13 | E12: Personal contratado | F12: Coincide (atributos según el modelo).
